[2025-04-28T17:39:08.970+0000] {taskinstance.py:1957} INFO - Dependencies all met for dep_context=non-requeueable deps ti=<TaskInstance: gen_data_daily.get_data_daily scheduled__2025-03-02T22:00:00+00:00 [queued]>
[2025-04-28T17:39:08.980+0000] {taskinstance.py:1957} INFO - Dependencies all met for dep_context=requeueable deps ti=<TaskInstance: gen_data_daily.get_data_daily scheduled__2025-03-02T22:00:00+00:00 [queued]>
[2025-04-28T17:39:08.980+0000] {taskinstance.py:2171} INFO - Starting attempt 2 of 2
[2025-04-28T17:39:08.995+0000] {taskinstance.py:2192} INFO - Executing <Task(BashOperator): get_data_daily> on 2025-03-02 22:00:00+00:00
[2025-04-28T17:39:09.001+0000] {standard_task_runner.py:60} INFO - Started process 70 to run task
[2025-04-28T17:39:09.007+0000] {standard_task_runner.py:87} INFO - Running: ['***', 'tasks', 'run', 'gen_data_daily', 'get_data_daily', 'scheduled__2025-03-02T22:00:00+00:00', '--job-id', '257', '--raw', '--subdir', 'DAGS_FOLDER/gen_data_daily.py', '--cfg-path', '/tmp/tmpns2i_gb9']
[2025-04-28T17:39:09.010+0000] {standard_task_runner.py:88} INFO - Job 257: Subtask get_data_daily
[2025-04-28T17:39:09.138+0000] {task_command.py:423} INFO - Running <TaskInstance: gen_data_daily.get_data_daily scheduled__2025-03-02T22:00:00+00:00 [running]> on host 45b38884c639
[2025-04-28T17:39:09.255+0000] {warnings.py:109} WARNING - /home/***/.local/lib/python3.8/site-packages/***/utils/context.py:207: AirflowContextDeprecationWarning: Accessing 'execution_date' from the template is deprecated and will be removed in a future version. Please use 'data_interval_start' or 'logical_date' instead.
  warnings.warn(_create_deprecation_warning(key, self._deprecation_replacements[key]))

[2025-04-28T17:39:09.341+0000] {taskinstance.py:2481} INFO - Exporting env vars: AIRFLOW_CTX_DAG_OWNER='longnv' AIRFLOW_CTX_DAG_ID='gen_data_daily' AIRFLOW_CTX_TASK_ID='get_data_daily' AIRFLOW_CTX_EXECUTION_DATE='2025-03-02T22:00:00+00:00' AIRFLOW_CTX_TRY_NUMBER='2' AIRFLOW_CTX_DAG_RUN_ID='scheduled__2025-03-02T22:00:00+00:00'
[2025-04-28T17:39:09.342+0000] {subprocess.py:63} INFO - Tmp dir root location: /tmp
[2025-04-28T17:39:09.342+0000] {subprocess.py:75} INFO - Running command: ['/usr/bin/bash', '-c', '\n        python /opt/***/external_scripts/step_1_2_get_transaction_data.py 2025-03-03\n        ']
[2025-04-28T17:39:09.355+0000] {subprocess.py:86} INFO - Output:
[2025-04-28T17:39:19.619+0000] {subprocess.py:93} INFO - :: loading settings :: url = jar:file:/opt/spark/jars/ivy-2.5.1.jar!/org/apache/ivy/core/settings/ivysettings.xml
[2025-04-28T17:39:19.918+0000] {subprocess.py:93} INFO - Ivy Default Cache set to: /home/***/.ivy2/cache
[2025-04-28T17:39:19.919+0000] {subprocess.py:93} INFO - The jars for the packages stored in: /home/***/.ivy2/jars
[2025-04-28T17:39:19.925+0000] {subprocess.py:93} INFO - org.apache.spark#spark-sql-kafka-0-10_2.12 added as a dependency
[2025-04-28T17:39:19.926+0000] {subprocess.py:93} INFO - io.delta#delta-core_2.12 added as a dependency
[2025-04-28T17:39:19.926+0000] {subprocess.py:93} INFO - org.apache.hadoop#hadoop-aws added as a dependency
[2025-04-28T17:39:19.926+0000] {subprocess.py:93} INFO - com.amazonaws#aws-java-sdk-bundle added as a dependency
[2025-04-28T17:39:19.927+0000] {subprocess.py:93} INFO - org.postgresql#postgresql added as a dependency
[2025-04-28T17:39:19.927+0000] {subprocess.py:93} INFO - :: resolving dependencies :: org.apache.spark#spark-submit-parent-b9153253-e891-4ebb-baa1-5a2c8afc06a5;1.0
[2025-04-28T17:39:19.927+0000] {subprocess.py:93} INFO - 	confs: [default]
[2025-04-28T17:39:20.356+0000] {subprocess.py:93} INFO - 	found org.apache.spark#spark-sql-kafka-0-10_2.12;3.4.1 in central
[2025-04-28T17:39:20.501+0000] {subprocess.py:93} INFO - 	found org.apache.spark#spark-token-provider-kafka-0-10_2.12;3.4.1 in central
[2025-04-28T17:39:20.558+0000] {subprocess.py:93} INFO - 	found org.apache.kafka#kafka-clients;3.3.2 in central
[2025-04-28T17:39:20.606+0000] {subprocess.py:93} INFO - 	found org.lz4#lz4-java;1.8.0 in central
[2025-04-28T17:39:20.633+0000] {subprocess.py:93} INFO - 	found org.xerial.snappy#snappy-java;1.1.10.1 in central
[2025-04-28T17:39:20.692+0000] {subprocess.py:93} INFO - 	found org.slf4j#slf4j-api;2.0.6 in central
[2025-04-28T17:39:20.750+0000] {subprocess.py:93} INFO - 	found org.apache.hadoop#hadoop-client-runtime;3.3.4 in central
[2025-04-28T17:39:20.864+0000] {subprocess.py:93} INFO - 	found org.apache.hadoop#hadoop-client-api;3.3.4 in central
[2025-04-28T17:39:20.924+0000] {subprocess.py:93} INFO - 	found commons-logging#commons-logging;1.1.3 in central
[2025-04-28T17:39:20.956+0000] {subprocess.py:93} INFO - 	found com.google.code.findbugs#jsr305;3.0.0 in central
[2025-04-28T17:39:20.975+0000] {subprocess.py:93} INFO - 	found org.apache.commons#commons-pool2;2.11.1 in central
[2025-04-28T17:39:21.000+0000] {subprocess.py:93} INFO - 	found io.delta#delta-core_2.12;2.4.0 in central
[2025-04-28T17:39:21.032+0000] {subprocess.py:93} INFO - 	found io.delta#delta-storage;2.4.0 in central
[2025-04-28T17:39:21.050+0000] {subprocess.py:93} INFO - 	found org.antlr#antlr4-runtime;4.9.3 in central
[2025-04-28T17:39:21.077+0000] {subprocess.py:93} INFO - 	found org.apache.hadoop#hadoop-aws;3.3.2 in central
[2025-04-28T17:39:21.128+0000] {subprocess.py:93} INFO - 	found org.wildfly.openssl#wildfly-openssl;1.0.7.Final in central
[2025-04-28T17:39:21.140+0000] {subprocess.py:93} INFO - 	found com.amazonaws#aws-java-sdk-bundle;1.12.261 in central
[2025-04-28T17:39:21.151+0000] {subprocess.py:93} INFO - 	found org.postgresql#postgresql;42.5.1 in central
[2025-04-28T17:39:21.165+0000] {subprocess.py:93} INFO - 	found org.checkerframework#checker-qual;3.5.0 in central
[2025-04-28T17:39:21.201+0000] {subprocess.py:93} INFO - :: resolution report :: resolve 1251ms :: artifacts dl 25ms
[2025-04-28T17:39:21.202+0000] {subprocess.py:93} INFO - 	:: modules in use:
[2025-04-28T17:39:21.202+0000] {subprocess.py:93} INFO - 	com.amazonaws#aws-java-sdk-bundle;1.12.261 from central in [default]
[2025-04-28T17:39:21.202+0000] {subprocess.py:93} INFO - 	com.google.code.findbugs#jsr305;3.0.0 from central in [default]
[2025-04-28T17:39:21.202+0000] {subprocess.py:93} INFO - 	commons-logging#commons-logging;1.1.3 from central in [default]
[2025-04-28T17:39:21.202+0000] {subprocess.py:93} INFO - 	io.delta#delta-core_2.12;2.4.0 from central in [default]
[2025-04-28T17:39:21.202+0000] {subprocess.py:93} INFO - 	io.delta#delta-storage;2.4.0 from central in [default]
[2025-04-28T17:39:21.202+0000] {subprocess.py:93} INFO - 	org.antlr#antlr4-runtime;4.9.3 from central in [default]
[2025-04-28T17:39:21.202+0000] {subprocess.py:93} INFO - 	org.apache.commons#commons-pool2;2.11.1 from central in [default]
[2025-04-28T17:39:21.202+0000] {subprocess.py:93} INFO - 	org.apache.hadoop#hadoop-aws;3.3.2 from central in [default]
[2025-04-28T17:39:21.203+0000] {subprocess.py:93} INFO - 	org.apache.hadoop#hadoop-client-api;3.3.4 from central in [default]
[2025-04-28T17:39:21.203+0000] {subprocess.py:93} INFO - 	org.apache.hadoop#hadoop-client-runtime;3.3.4 from central in [default]
[2025-04-28T17:39:21.203+0000] {subprocess.py:93} INFO - 	org.apache.kafka#kafka-clients;3.3.2 from central in [default]
[2025-04-28T17:39:21.203+0000] {subprocess.py:93} INFO - 	org.apache.spark#spark-sql-kafka-0-10_2.12;3.4.1 from central in [default]
[2025-04-28T17:39:21.203+0000] {subprocess.py:93} INFO - 	org.apache.spark#spark-token-provider-kafka-0-10_2.12;3.4.1 from central in [default]
[2025-04-28T17:39:21.203+0000] {subprocess.py:93} INFO - 	org.checkerframework#checker-qual;3.5.0 from central in [default]
[2025-04-28T17:39:21.203+0000] {subprocess.py:93} INFO - 	org.lz4#lz4-java;1.8.0 from central in [default]
[2025-04-28T17:39:21.203+0000] {subprocess.py:93} INFO - 	org.postgresql#postgresql;42.5.1 from central in [default]
[2025-04-28T17:39:21.203+0000] {subprocess.py:93} INFO - 	org.slf4j#slf4j-api;2.0.6 from central in [default]
[2025-04-28T17:39:21.204+0000] {subprocess.py:93} INFO - 	org.wildfly.openssl#wildfly-openssl;1.0.7.Final from central in [default]
[2025-04-28T17:39:21.204+0000] {subprocess.py:93} INFO - 	org.xerial.snappy#snappy-java;1.1.10.1 from central in [default]
[2025-04-28T17:39:21.204+0000] {subprocess.py:93} INFO - 	:: evicted modules:
[2025-04-28T17:39:21.204+0000] {subprocess.py:93} INFO - 	com.amazonaws#aws-java-sdk-bundle;1.11.1026 by [com.amazonaws#aws-java-sdk-bundle;1.12.261] in [default]
[2025-04-28T17:39:21.204+0000] {subprocess.py:93} INFO - 	---------------------------------------------------------------------
[2025-04-28T17:39:21.204+0000] {subprocess.py:93} INFO - 	|                  |            modules            ||   artifacts   |
[2025-04-28T17:39:21.204+0000] {subprocess.py:93} INFO - 	|       conf       | number| search|dwnlded|evicted|| number|dwnlded|
[2025-04-28T17:39:21.204+0000] {subprocess.py:93} INFO - 	---------------------------------------------------------------------
[2025-04-28T17:39:21.204+0000] {subprocess.py:93} INFO - 	|      default     |   20  |   0   |   0   |   1   ||   19  |   0   |
[2025-04-28T17:39:21.204+0000] {subprocess.py:93} INFO - 	---------------------------------------------------------------------
[2025-04-28T17:39:21.227+0000] {subprocess.py:93} INFO - :: retrieving :: org.apache.spark#spark-submit-parent-b9153253-e891-4ebb-baa1-5a2c8afc06a5
[2025-04-28T17:39:21.228+0000] {subprocess.py:93} INFO - 	confs: [default]
[2025-04-28T17:39:21.241+0000] {subprocess.py:93} INFO - 	0 artifacts copied, 19 already retrieved (0kB/18ms)
[2025-04-28T17:39:22.158+0000] {subprocess.py:93} INFO - 25/04/28 17:39:22 WARN NativeCodeLoader: Unable to load native-hadoop library for your platform... using builtin-java classes where applicable
[2025-04-28T17:39:22.692+0000] {subprocess.py:93} INFO - Setting default log level to "WARN".
[2025-04-28T17:39:22.692+0000] {subprocess.py:93} INFO - To adjust logging level use sc.setLogLevel(newLevel). For SparkR, use setLogLevel(newLevel).
[2025-04-28T17:39:29.271+0000] {job.py:213} ERROR - Job heartbeat got an exception
Traceback (most recent call last):
  File "/home/airflow/.local/lib/python3.8/site-packages/sqlalchemy/engine/base.py", line 3371, in _wrap_pool_connect
    return fn()
  File "/home/airflow/.local/lib/python3.8/site-packages/sqlalchemy/pool/base.py", line 327, in connect
    return _ConnectionFairy._checkout(self)
  File "/home/airflow/.local/lib/python3.8/site-packages/sqlalchemy/pool/base.py", line 894, in _checkout
    fairy = _ConnectionRecord.checkout(pool)
  File "/home/airflow/.local/lib/python3.8/site-packages/sqlalchemy/pool/base.py", line 493, in checkout
    rec = pool._do_get()
  File "/home/airflow/.local/lib/python3.8/site-packages/sqlalchemy/pool/impl.py", line 256, in _do_get
    return self._create_connection()
  File "/home/airflow/.local/lib/python3.8/site-packages/sqlalchemy/pool/base.py", line 273, in _create_connection
    return _ConnectionRecord(self)
  File "/home/airflow/.local/lib/python3.8/site-packages/sqlalchemy/pool/base.py", line 388, in __init__
    self.__connect()
  File "/home/airflow/.local/lib/python3.8/site-packages/sqlalchemy/pool/base.py", line 691, in __connect
    pool.logger.debug("Error on connect(): %s", e)
  File "/home/airflow/.local/lib/python3.8/site-packages/sqlalchemy/util/langhelpers.py", line 70, in __exit__
    compat.raise_(
  File "/home/airflow/.local/lib/python3.8/site-packages/sqlalchemy/util/compat.py", line 211, in raise_
    raise exception
  File "/home/airflow/.local/lib/python3.8/site-packages/sqlalchemy/pool/base.py", line 686, in __connect
    self.dbapi_connection = connection = pool._invoke_creator(self)
  File "/home/airflow/.local/lib/python3.8/site-packages/sqlalchemy/engine/create.py", line 574, in connect
    return dialect.connect(*cargs, **cparams)
  File "/home/airflow/.local/lib/python3.8/site-packages/sqlalchemy/engine/default.py", line 598, in connect
    return self.dbapi.connect(*cargs, **cparams)
  File "/home/airflow/.local/lib/python3.8/site-packages/psycopg2/__init__.py", line 122, in connect
    conn = _connect(dsn, connection_factory=connection_factory, **kwasync)
psycopg2.OperationalError: connection to server at "postgres" (172.18.0.5), port 5432 failed: FATAL:  the database system is shutting down


The above exception was the direct cause of the following exception:

Traceback (most recent call last):
  File "/home/airflow/.local/lib/python3.8/site-packages/airflow/jobs/job.py", line 187, in heartbeat
    self._merge_from(Job._fetch_from_db(self, session))
  File "/home/airflow/.local/lib/python3.8/site-packages/airflow/api_internal/internal_api_call.py", line 114, in wrapper
    return func(*args, **kwargs)
  File "/home/airflow/.local/lib/python3.8/site-packages/airflow/utils/session.py", line 76, in wrapper
    return func(*args, **kwargs)
  File "/home/airflow/.local/lib/python3.8/site-packages/airflow/jobs/job.py", line 308, in _fetch_from_db
    session.merge(job)
  File "/home/airflow/.local/lib/python3.8/site-packages/sqlalchemy/orm/session.py", line 3056, in merge
    return self._merge(
  File "/home/airflow/.local/lib/python3.8/site-packages/sqlalchemy/orm/session.py", line 3136, in _merge
    merged = self.get(
  File "/home/airflow/.local/lib/python3.8/site-packages/sqlalchemy/orm/session.py", line 2853, in get
    return self._get_impl(
  File "/home/airflow/.local/lib/python3.8/site-packages/sqlalchemy/orm/session.py", line 2975, in _get_impl
    return db_load_fn(
  File "/home/airflow/.local/lib/python3.8/site-packages/sqlalchemy/orm/loading.py", line 530, in load_on_pk_identity
    session.execute(
  File "/home/airflow/.local/lib/python3.8/site-packages/sqlalchemy/orm/session.py", line 1716, in execute
    conn = self._connection_for_bind(bind)
  File "/home/airflow/.local/lib/python3.8/site-packages/sqlalchemy/orm/session.py", line 1555, in _connection_for_bind
    return self._transaction._connection_for_bind(
  File "/home/airflow/.local/lib/python3.8/site-packages/sqlalchemy/orm/session.py", line 750, in _connection_for_bind
    conn = bind.connect()
  File "/home/airflow/.local/lib/python3.8/site-packages/sqlalchemy/future/engine.py", line 406, in connect
    return super(Engine, self).connect()
  File "/home/airflow/.local/lib/python3.8/site-packages/sqlalchemy/engine/base.py", line 3325, in connect
    return self._connection_cls(self, close_with_result=close_with_result)
  File "/home/airflow/.local/lib/python3.8/site-packages/sqlalchemy/engine/base.py", line 96, in __init__
    else engine.raw_connection()
  File "/home/airflow/.local/lib/python3.8/site-packages/sqlalchemy/engine/base.py", line 3404, in raw_connection
    return self._wrap_pool_connect(self.pool.connect, _connection)
  File "/home/airflow/.local/lib/python3.8/site-packages/sqlalchemy/engine/base.py", line 3374, in _wrap_pool_connect
    Connection._handle_dbapi_exception_noconnection(
  File "/home/airflow/.local/lib/python3.8/site-packages/sqlalchemy/engine/base.py", line 2208, in _handle_dbapi_exception_noconnection
    util.raise_(
  File "/home/airflow/.local/lib/python3.8/site-packages/sqlalchemy/util/compat.py", line 211, in raise_
    raise exception
  File "/home/airflow/.local/lib/python3.8/site-packages/sqlalchemy/engine/base.py", line 3371, in _wrap_pool_connect
    return fn()
  File "/home/airflow/.local/lib/python3.8/site-packages/sqlalchemy/pool/base.py", line 327, in connect
    return _ConnectionFairy._checkout(self)
  File "/home/airflow/.local/lib/python3.8/site-packages/sqlalchemy/pool/base.py", line 894, in _checkout
    fairy = _ConnectionRecord.checkout(pool)
  File "/home/airflow/.local/lib/python3.8/site-packages/sqlalchemy/pool/base.py", line 493, in checkout
    rec = pool._do_get()
  File "/home/airflow/.local/lib/python3.8/site-packages/sqlalchemy/pool/impl.py", line 256, in _do_get
    return self._create_connection()
  File "/home/airflow/.local/lib/python3.8/site-packages/sqlalchemy/pool/base.py", line 273, in _create_connection
    return _ConnectionRecord(self)
  File "/home/airflow/.local/lib/python3.8/site-packages/sqlalchemy/pool/base.py", line 388, in __init__
    self.__connect()
  File "/home/airflow/.local/lib/python3.8/site-packages/sqlalchemy/pool/base.py", line 691, in __connect
    pool.logger.debug("Error on connect(): %s", e)
  File "/home/airflow/.local/lib/python3.8/site-packages/sqlalchemy/util/langhelpers.py", line 70, in __exit__
    compat.raise_(
  File "/home/airflow/.local/lib/python3.8/site-packages/sqlalchemy/util/compat.py", line 211, in raise_
    raise exception
  File "/home/airflow/.local/lib/python3.8/site-packages/sqlalchemy/pool/base.py", line 686, in __connect
    self.dbapi_connection = connection = pool._invoke_creator(self)
  File "/home/airflow/.local/lib/python3.8/site-packages/sqlalchemy/engine/create.py", line 574, in connect
    return dialect.connect(*cargs, **cparams)
  File "/home/airflow/.local/lib/python3.8/site-packages/sqlalchemy/engine/default.py", line 598, in connect
    return self.dbapi.connect(*cargs, **cparams)
  File "/home/airflow/.local/lib/python3.8/site-packages/psycopg2/__init__.py", line 122, in connect
    conn = _connect(dsn, connection_factory=connection_factory, **kwasync)
sqlalchemy.exc.OperationalError: (psycopg2.OperationalError) connection to server at "postgres" (172.18.0.5), port 5432 failed: FATAL:  the database system is shutting down

(Background on this error at: https://sqlalche.me/e/14/e3q8)
[2025-04-28T17:39:29.276+0000] {job.py:216} ERROR - Job heartbeat failed with error. Scheduler may go into unhealthy state
[2025-04-28T17:39:34.295+0000] {job.py:216} ERROR - Job heartbeat failed with error. Scheduler may go into unhealthy state
