[2025-04-02T18:38:23.825+0000] {taskinstance.py:1957} INFO - Dependencies all met for dep_context=non-requeueable deps ti=<TaskInstance: gen_lxw_fts.calculate_fts scheduled__2025-03-09T23:00:00+00:00 [queued]>
[2025-04-02T18:38:23.835+0000] {taskinstance.py:1957} INFO - Dependencies all met for dep_context=requeueable deps ti=<TaskInstance: gen_lxw_fts.calculate_fts scheduled__2025-03-09T23:00:00+00:00 [queued]>
[2025-04-02T18:38:23.835+0000] {taskinstance.py:2171} INFO - Starting attempt 3 of 4
[2025-04-02T18:38:23.849+0000] {taskinstance.py:2192} INFO - Executing <Task(BashOperator): calculate_fts> on 2025-03-09 23:00:00+00:00
[2025-04-02T18:38:23.857+0000] {standard_task_runner.py:60} INFO - Started process 11482 to run task
[2025-04-02T18:38:23.866+0000] {standard_task_runner.py:87} INFO - Running: ['***', 'tasks', 'run', 'gen_lxw_fts', 'calculate_fts', 'scheduled__2025-03-09T23:00:00+00:00', '--job-id', '83', '--raw', '--subdir', 'DAGS_FOLDER/gen_lxw_fts.py', '--cfg-path', '/tmp/tmphmts22nm']
[2025-04-02T18:38:23.867+0000] {standard_task_runner.py:88} INFO - Job 83: Subtask calculate_fts
[2025-04-02T18:38:23.939+0000] {task_command.py:423} INFO - Running <TaskInstance: gen_lxw_fts.calculate_fts scheduled__2025-03-09T23:00:00+00:00 [running]> on host 4a8602fc40fd
[2025-04-02T18:38:24.050+0000] {warnings.py:109} WARNING - /home/***/.local/lib/python3.8/site-packages/***/utils/context.py:207: AirflowContextDeprecationWarning: Accessing 'execution_date' from the template is deprecated and will be removed in a future version. Please use 'data_interval_start' or 'logical_date' instead.
  warnings.warn(_create_deprecation_warning(key, self._deprecation_replacements[key]))

[2025-04-02T18:38:24.096+0000] {taskinstance.py:2481} INFO - Exporting env vars: AIRFLOW_CTX_DAG_OWNER='longnv' AIRFLOW_CTX_DAG_ID='gen_lxw_fts' AIRFLOW_CTX_TASK_ID='calculate_fts' AIRFLOW_CTX_EXECUTION_DATE='2025-03-09T23:00:00+00:00' AIRFLOW_CTX_TRY_NUMBER='3' AIRFLOW_CTX_DAG_RUN_ID='scheduled__2025-03-09T23:00:00+00:00'
[2025-04-02T18:38:24.098+0000] {subprocess.py:63} INFO - Tmp dir root location: /tmp
[2025-04-02T18:38:24.098+0000] {subprocess.py:75} INFO - Running command: ['/usr/bin/bash', '-c', '\n        python /opt/***/external_scripts/2_calculate_features.py 2025-03-10\n        ']
[2025-04-02T18:38:24.114+0000] {subprocess.py:86} INFO - Output:
[2025-04-02T18:38:40.903+0000] {subprocess.py:93} INFO - :: loading settings :: url = jar:file:/opt/spark/jars/ivy-2.5.1.jar!/org/apache/ivy/core/settings/ivysettings.xml
[2025-04-02T18:38:41.886+0000] {subprocess.py:93} INFO - Ivy Default Cache set to: /home/***/.ivy2/cache
[2025-04-02T18:38:41.889+0000] {subprocess.py:93} INFO - The jars for the packages stored in: /home/***/.ivy2/jars
[2025-04-02T18:38:41.914+0000] {subprocess.py:93} INFO - org.apache.spark#spark-sql-kafka-0-10_2.12 added as a dependency
[2025-04-02T18:38:41.919+0000] {subprocess.py:93} INFO - io.delta#delta-core_2.12 added as a dependency
[2025-04-02T18:38:41.919+0000] {subprocess.py:93} INFO - org.apache.hadoop#hadoop-aws added as a dependency
[2025-04-02T18:38:41.919+0000] {subprocess.py:93} INFO - com.amazonaws#aws-java-sdk-bundle added as a dependency
[2025-04-02T18:38:41.920+0000] {subprocess.py:93} INFO - org.postgresql#postgresql added as a dependency
[2025-04-02T18:38:41.927+0000] {subprocess.py:93} INFO - :: resolving dependencies :: org.apache.spark#spark-submit-parent-cdeb246d-0dd1-4a30-8889-b9842fca790a;1.0
[2025-04-02T18:38:41.928+0000] {subprocess.py:93} INFO - 	confs: [default]
[2025-04-02T18:38:43.018+0000] {subprocess.py:93} INFO - 	found org.apache.spark#spark-sql-kafka-0-10_2.12;3.4.1 in central
[2025-04-02T18:38:43.449+0000] {subprocess.py:93} INFO - 	found org.apache.spark#spark-token-provider-kafka-0-10_2.12;3.4.1 in central
[2025-04-02T18:38:43.650+0000] {subprocess.py:93} INFO - 	found org.apache.kafka#kafka-clients;3.3.2 in central
[2025-04-02T18:38:43.869+0000] {subprocess.py:93} INFO - 	found org.lz4#lz4-java;1.8.0 in central
[2025-04-02T18:38:43.961+0000] {subprocess.py:93} INFO - 	found org.xerial.snappy#snappy-java;1.1.10.1 in central
[2025-04-02T18:38:43.981+0000] {subprocess.py:93} INFO - 	found org.slf4j#slf4j-api;2.0.6 in central
[2025-04-02T18:38:44.124+0000] {subprocess.py:93} INFO - 	found org.apache.hadoop#hadoop-client-runtime;3.3.4 in central
[2025-04-02T18:38:44.212+0000] {subprocess.py:93} INFO - 	found org.apache.hadoop#hadoop-client-api;3.3.4 in central
[2025-04-02T18:38:44.232+0000] {local_task_job_runner.py:302} WARNING - State of this instance has been externally set to scheduled. Terminating instance.
[2025-04-02T18:38:44.233+0000] {process_utils.py:131} INFO - Sending 15 to group 11482. PIDs of all processes in the group: [11483, 11484, 11492, 11482]
[2025-04-02T18:38:44.234+0000] {process_utils.py:86} INFO - Sending the signal 15 to group 11482
[2025-04-02T18:38:44.238+0000] {taskinstance.py:2451} ERROR - Received SIGTERM. Terminating subprocesses.
[2025-04-02T18:38:44.239+0000] {subprocess.py:104} INFO - Sending SIGTERM signal to process group
[2025-04-02T18:38:44.290+0000] {process_utils.py:79} INFO - Process psutil.Process(pid=11484, status='terminated', started='18:38:23') (11484) terminated with exit code None
[2025-04-02T18:38:44.275+0000] {taskinstance.py:2699} ERROR - Task failed with exception
Traceback (most recent call last):
  File "/home/airflow/.local/lib/python3.8/site-packages/airflow/models/taskinstance.py", line 433, in _execute_task
    result = execute_callable(context=context, **execute_callable_kwargs)
  File "/home/airflow/.local/lib/python3.8/site-packages/airflow/operators/bash.py", line 203, in execute
    result = self.subprocess_hook.run_command(
  File "/home/airflow/.local/lib/python3.8/site-packages/airflow/hooks/subprocess.py", line 91, in run_command
    for raw_line in iter(self.sub_process.stdout.readline, b""):
  File "/home/airflow/.local/lib/python3.8/site-packages/airflow/models/taskinstance.py", line 2453, in signal_handler
    raise AirflowException("Task received SIGTERM signal")
airflow.exceptions.AirflowException: Task received SIGTERM signal
[2025-04-02T18:38:44.324+0000] {taskinstance.py:1138} INFO - Marking task as UP_FOR_RETRY. dag_id=gen_lxw_fts, task_id=calculate_fts, execution_date=20250309T230000, start_date=20250402T183823, end_date=20250402T183844
[2025-04-02T18:38:44.391+0000] {standard_task_runner.py:107} ERROR - Failed to execute job 83 for task calculate_fts (Task received SIGTERM signal; 11482)
[2025-04-02T18:38:44.449+0000] {process_utils.py:79} INFO - Process psutil.Process(pid=11482, status='terminated', exitcode=1, started='18:38:23') (11482) terminated with exit code 1
[2025-04-02T18:38:44.450+0000] {process_utils.py:79} INFO - Process psutil.Process(pid=11483, status='terminated', started='18:38:23') (11483) terminated with exit code None
[2025-04-02T18:38:44.450+0000] {process_utils.py:79} INFO - Process psutil.Process(pid=11492, status='terminated', started='18:38:27') (11492) terminated with exit code None
